<?xml version="1.0" ?>
<!-- =================================================================================== -->
<!-- |    This document was autogenerated by xacro from /home/gustavo/ros_ws/biped_ws/src/uv_biped/scripts/../robots/uv_biped.urdf.xacro | -->
<!-- |    EDITING THIS FILE BY HAND IS NOT RECOMMENDED                                 | -->
<!-- =================================================================================== -->
<robot name="uv_biped">
  <link name="l_clav">
    <inertial>
      <mass value="2.369"/>
      <origin rpy="0 -0 0" xyz="0.014 0.058 0.029"/>
      <inertia ixx="0.004" ixy="0.001" ixz="0" iyy="0.006" iyz="0" izz="0.007"/>
    </inertial>
    <visual>
      <origin rpy="1.04719755 0 0" xyz="0 0 0"/>
      <geometry>
        <mesh filename="package://atlas/meshes/l_clav.dae" scale="1 1 1"/>
      </geometry>
    </visual>
    <collision group="default">
      <origin rpy="0 1.5707963267949 0" xyz="0 0.0697 0.0261"/>
      <geometry>
        <cylinder length="0.1525" radius="0.045"/>
      </geometry>
    </collision>
    <collision group="other">
      <origin rpy="1.0472 0 0" xyz="-0.005 -0.0074 -0.0538"/>
      <geometry>
        <box size="0.13 0.15 0.05"/>
      </geometry>
    </collision>
  </link>
  <link name="l_farm">
    <inertial>
      <mass value="0.981"/>
      <origin rpy="0 -0 0" xyz="0 0.041 0"/>
      <inertia ixx="0.003" ixy="0" ixz="0" iyy="0.001" iyz="0" izz="0.003"/>
    </inertial>
    <visual>
      <origin rpy="0 -0 0" xyz="0 -0.06 0"/>
      <geometry>
        <mesh filename="package://atlas/meshes/l_farm.dae" scale="1 1 1"/>
      </geometry>
    </visual>
    <collision group="default">
      <origin rpy="0 1.5708 0" xyz="0.0 0.065 0.004"/>
      <geometry>
        <cylinder length="0.125" radius="0.045"/>
      </geometry>
    </collision>
    <collision group="other">
      <origin rpy="0 0 0" xyz="0.001 0.015 -0.002"/>
      <geometry>
        <box size="0.135 0.1 0.045"/>
      </geometry>
    </collision>
  </link>
  <link name="l_foot">
    <inertial>
      <mass value="0.867"/>
      <origin rpy="0 -0 0" xyz="0.027 0 -0.067"/>
      <inertia ixx="0.002" ixy="0" ixz="0" iyy="0.00350421" iyz="0" izz="0.00400651"/>
    </inertial>
    <visual>
      <origin rpy="0 -0 0" xyz="0 0 0"/>
      <geometry>
        <mesh filename="package://atlas/meshes/l_foot.dae" scale="1 1 1"/>
      </geometry>
    </visual>
    <!-- bottom -->
    <collision group="default">
      <origin rpy="0 0 0" xyz="0.048 0 -0.056119"/>
      <geometry>
        <box size="0.26 0.124887 0.05"/>
      </geometry>
    </collision>
    <!-- ankle FIXME: adding this collision body destabilizes robot, shouldn't
        <collision group="other">
          <origin xyz="0.0 0 -0.0528735" rpy="0 0 0"/>
          <geometry>
            <cylinder radius="0.0373" length="0.037827"/>
          </geometry>
        </collision>
        -->
  </link>
  <link name="l_hand">
    <inertial>
      <mass value="2.263"/>
      <origin rpy="0 -0 0" xyz="0 0.093 0"/>
      <inertia ixx="0.01" ixy="0" ixz="0" iyy="0.002" iyz="0" izz="0.01"/>
    </inertial>
    <visual>
      <origin rpy="0 -0 0" xyz="0 0 0"/>
      <geometry>
        <mesh filename="package://atlas/meshes/l_hand.dae" scale="1 1 1"/>
      </geometry>
    </visual>
    <collision group="default">
      <origin rpy="1.5707963267949 0 0" xyz="0.001 0.1 0.01"/>
      <geometry>
        <cylinder length="0.05" radius="0.03"/>
      </geometry>
    </collision>
    <collision group="other">
      <origin rpy="0 0 0" xyz="0.001 0.05 0.01"/>
      <geometry>
        <box size="0.13 0.09 0.07"/>
      </geometry>
    </collision>
  </link>
  <link name="l_larm">
    <inertial>
      <mass value="2.148"/>
      <origin rpy="0 -0 0" xyz="-0.003 0.099 -0.014"/>
      <inertia ixx="0.005" ixy="0" ixz="0" iyy="0.003" iyz="0" izz="0.006"/>
    </inertial>
    <visual>
      <origin rpy="0 -0 0" xyz="0 0 0"/>
      <geometry>
        <mesh filename="package://atlas/meshes/l_larm.dae" scale="1 1 1"/>
      </geometry>
    </visual>
    <collision group="default">
      <origin rpy="1.5707963267949 0 0" xyz="0.001 0.127 0.00"/>
      <geometry>
        <cylinder length="0.125" radius="0.045"/>
      </geometry>
    </collision>
    <collision group="other">
      <origin rpy="0 0 0" xyz="0.001 0.051 0.0"/>
      <geometry>
        <box size="0.135 0.15 0.06"/>
      </geometry>
    </collision>
  </link>
  <link name="l_lglut">
    <inertial>
      <mass value="0.803"/>
      <origin rpy="0 -0 0" xyz="0.0133341 0.0170484 -0.0312052"/>
      <inertia ixx="0.0453457" ixy="-2.24344e-05" ixz="2.50508e-06" iyy="0.0174182" iyz="0.000137862" izz="0.0071591"/>
    </inertial>
    <visual>
      <origin rpy="0 -0 0" xyz="0 0 0"/>
      <geometry>
        <mesh filename="package://atlas/meshes/l_lglut.dae" scale="1 1 1"/>
      </geometry>
    </visual>
    <collision group="default">
      <origin rpy="1.5707963267949 0 0" xyz="0.049968 0.022488 -0.0501165"/>
      <geometry>
        <cylinder length="0.060306" radius="0.02009687"/>
      </geometry>
    </collision>
    <collision group="other">
      <origin rpy="0 1.5707963267949 0" xyz="0 0 0"/>
      <geometry>
        <cylinder length="0.12" radius="0.02"/>
      </geometry>
    </collision>
  </link>
  <link name="l_lleg">
    <inertial>
      <mass value="4.367"/>
      <origin rpy="0 -0 0" xyz="0.001 0 -0.187"/>
      <inertia ixx="0.077" ixy="0" ixz="-0.003" iyy="0.076" iyz="0" izz="0.01"/>
    </inertial>
    <visual>
      <origin rpy="0 -0 0" xyz="0 0 0"/>
      <geometry>
        <mesh filename="package://atlas/meshes/l_lleg.dae" scale="1.0 1.0 1.0"/>
      </geometry>
    </visual>
    <collision group="default">
      <origin rpy="0 0.10 0" xyz="0.02 0.00295 -0.18"/>
      <geometry>
        <cylinder length="0.40" radius="0.07"/>
      </geometry>
    </collision>
  </link>
  <link name="l_scap">
    <inertial>
      <mass value="2.707"/>
      <origin rpy="0 -0 0" xyz="-0.002 0.108 0"/>
      <inertia ixx="0.01" ixy="0" ixz="0" iyy="0.005" iyz="0" izz="0.013"/>
    </inertial>
    <visual>
      <origin rpy="0 0 0" xyz="0 0 0"/>
      <geometry>
        <mesh filename="package://atlas/meshes/l_scap.dae" scale="1 1 1"/>
      </geometry>
    </visual>
    <collision group="default">
      <origin rpy="1.5707963267949 0 0" xyz="0.001 0.12651 0.01521"/>
      <geometry>
        <cylinder length="0.125" radius="0.045"/>
      </geometry>
    </collision>
    <collision group="other">
      <origin rpy="0 0 0" xyz="0.001 0.05 0.016"/>
      <geometry>
        <box size="0.15 0.15 0.06"/>
      </geometry>
    </collision>
  </link>
  <link name="l_talus">
    <inertial>
      <mass value="0.867"/>
      <origin rpy="0 -0 0" xyz="0 0 0"/>
      <inertia ixx="0.001" ixy="0" ixz="0" iyy="0.00350421" iyz="0" izz="0.00400651"/>
    </inertial>
    <visual>
      <origin rpy="0 -0 0" xyz="0 0 0"/>
      <geometry>
        <mesh filename="package://atlas/meshes/l_talus.dae" scale="1 1 1"/>
      </geometry>
    </visual>
    <collision group="default">
      <origin rpy="0 1.5707963267949 0" xyz="0 0 0"/>
      <geometry>
        <cylinder length="0.029542" radius="0.010181"/>
      </geometry>
    </collision>
    <collision group="other">
      <origin rpy="1.5707963267949 0 0" xyz="0 0 0"/>
      <geometry>
        <cylinder length="0.010059" radius="0.010348"/>
      </geometry>
    </collision>
  </link>
  <link name="l_uarm">
    <inertial>
      <mass value="1.881"/>
      <origin rpy="0 -0 0" xyz="0.007 0.114 0.008"/>
      <inertia ixx="0.002" ixy="0" ixz="0" iyy="0.003" iyz="0" izz="0.003"/>
    </inertial>
    <visual>
      <origin rpy="0 -0 0" xyz="0 0 0"/>
      <geometry>
        <mesh filename="package://atlas/meshes/l_uarm.dae" scale="1 1 1"/>
      </geometry>
    </visual>
    <collision group="default">
      <origin rpy="0 1.5708 0" xyz="0.001 0.111 0.0"/>
      <geometry>
        <cylinder length="0.125" radius="0.045"/>
      </geometry>
    </collision>
    <collision group="other">
      <origin rpy="0 1.5707963267949 0" xyz="0.001 0.043 0.01"/>
      <geometry>
        <box size="0.04 0.07 0.13"/>
      </geometry>
    </collision>
  </link>
  <link name="l_uglut">
    <inertial>
      <mass value="1.51622"/>
      <origin rpy="0 -0 0" xyz="0.00529262 -0.00344732 0.00313046"/>
      <inertia ixx="0.0327037" ixy="-3.79607e-08" ixz="-2.79549e-05" iyy="0.0174182" iyz="-3.2735e-08" izz="0.0071591"/>
    </inertial>
    <visual>
      <origin rpy="0 -0 0" xyz="0 0 0"/>
      <geometry>
        <mesh filename="package://atlas/meshes/l_uglut.dae" scale="1 1 1"/>
      </geometry>
    </visual>
    <collision group="default">
      <origin rpy="0 1.5707963267949 0" xyz="0 0 0"/>
      <geometry>
        <cylinder length="0.078396" radius="0.019096"/>
      </geometry>
    </collision>
    <collision group="other">
      <origin rpy="0 0 0" xyz="0 0 0"/>
      <geometry>
        <cylinder length="0.080842" radius="0.019841"/>
      </geometry>
    </collision>
  </link>
  <link name="l_uleg">
    <inertial>
      <mass value="7.227"/>
      <origin rpy="0 -0 0" xyz="0 0 -0.21"/>
      <inertia ixx="0.0453457" ixy="0" ixz="0" iyy="0.09" iyz="0" izz="0.0071591"/>
    </inertial>
    <visual>
      <origin rpy="0 -0 0" xyz="0 0 0"/>
      <geometry>
        <mesh filename="package://atlas/meshes/l_uleg.dae" scale="1.0 1.0 1.0"/>
      </geometry>
    </visual>
    <collision group="default">
      <origin rpy="0 0 0" xyz="-0.0179 0.02085 -0.13"/>
      <geometry>
        <cylinder length="0.10" radius="0.1"/>
      </geometry>
    </collision>
    <collision group="other">
      <origin rpy="0 -0.3 0" xyz="-0.03 0.01 -0.23"/>
      <geometry>
        <cylinder length="0.15" radius="0.07"/>
      </geometry>
    </collision>
    <collision group="other">
      <origin rpy="0 0.3 0" xyz="-0.005 0.01 -0.23"/>
      <geometry>
        <cylinder length="0.15" radius="0.07"/>
      </geometry>
    </collision>
    <collision group="other">
      <origin rpy="-0.25 0 0" xyz="-0.02 0.03 -0.23"/>
      <geometry>
        <cylinder length="0.15" radius="0.07"/>
      </geometry>
    </collision>
  </link>
  <link name="ltorso">
    <inertial>
      <mass value="1.62729"/>
      <origin rpy="0 -0 0" xyz="-0.0112984 -3.15366e-06 0.0746835"/>
      <inertia ixx="0.0646646" ixy="-5.04491e-08" ixz="-0.000342157" iyy="0.050298" iyz="4.87119e-07" izz="0.10973"/>
    </inertial>
    <visual>
      <origin rpy="0 -0 0" xyz="0 0 0"/>
      <geometry>
        <mesh filename="package://atlas/meshes/ltorso.dae" scale="1 1 1"/>
      </geometry>
    </visual>
    <!-- this part is completely internal
        <collision group="default">
          <origin rpy="0 0 0" xyz="0 0 0.039762"/>
          <geometry>
            <cylinder radius="0.025918" length="0.076922"/>
          </geometry>
        </collision>
        <collision group="other">
          <origin rpy="1.5707963267949 0 0" xyz="0 0.0250065 0.09025"/>
          <geometry>
            <cylinder radius="0.014828" length="0.020367"/>
          </geometry>
        </collision>
        <collision group="other">
          <origin rpy="1.5707963267949 0 0" xyz="0 -0.0248895 0.09025"/>
          <geometry>
            <cylinder radius="0.014828" length="0.020169"/>
          </geometry>
        </collision>
        -->
  </link>
  <link name="mtorso">
    <inertial>
      <mass value="3.8068"/>
      <origin rpy="0 -0 0" xyz="-0.00816266 -0.0131245 0.0305974"/>
      <inertia ixx="0.1975" ixy="-6.10764e-05" ixz="3.94009e-05" iyy="0.544742" iyz="5.27463e-05" izz="0.10973"/>
    </inertial>
    <visual>
      <origin rpy="0 -0 0" xyz="0 0 0"/>
      <geometry>
        <mesh filename="package://atlas/meshes/mtorso.dae" scale="1 1 1"/>
      </geometry>
    </visual>
    <collision group="default">
      <origin rpy="1.5707963267949 0 0" xyz="0 0 0"/>
      <geometry>
        <cylinder length="0.03" radius="0.017"/>
      </geometry>
    </collision>
    <collision group="other">
      <origin rpy="0 1.5707963267949 0" xyz="0.0285 0 0.05"/>
      <geometry>
        <cylinder length="0.02" radius="0.015"/>
      </geometry>
    </collision>
    <collision group="other">
      <origin rpy="0 1.5707963267949 0" xyz="-0.0285 0 0.05"/>
      <geometry>
        <cylinder length="0.02" radius="0.015"/>
      </geometry>
    </collision>
  </link>
  <link name="pelvis">
    <inertial>
      <mass value="12.54638"/>
      <origin rpy="0 -0 0" xyz="0.0111 0 0.0271"/>
      <inertia ixx="0.0327037" ixy="0.0008" ixz="-0.0007" iyy="0.0174182" iyz="-0.0005" izz="0.118059"/>
    </inertial>
    <visual>
      <origin rpy="0 -0 0" xyz="0 0 0"/>
      <geometry>
        <mesh filename="package://atlas/meshes/pelvis.dae" scale="1.0 1.0 1.0"/>
      </geometry>
    </visual>
    <collision group="default">
      <origin rpy="1.5707963267949 0 0" xyz="0.046 0.0 -0.02"/>
      <geometry>
        <cylinder length="0.06" radius="0.11"/>
      </geometry>
    </collision>
    <collision group="other">
      <origin rpy="1.5707963267949 0 0" xyz="-0.03 0.0 -0.02"/>
      <geometry>
        <cylinder length="0.06" radius="0.11"/>
      </geometry>
    </collision>
    <collision group="other">
      <origin rpy="0 0 0" xyz="0.01 0.042 0.09"/>
      <geometry>
        <cylinder length="0.05" radius="0.16"/>
      </geometry>
    </collision>
    <collision group="other">
      <origin rpy="0 0 0" xyz="0.01 -0.042 0.09"/>
      <geometry>
        <cylinder length="0.05" radius="0.16"/>
      </geometry>
    </collision>
    <collision group="other">
      <origin rpy="0 0 0" xyz="-0.1 0 -0.05"/>
      <geometry>
        <box size="0.1 0.15 0.2"/>
      </geometry>
    </collision>
  </link>
  <link name="r_clav">
    <inertial>
      <mass value="2.369"/>
      <origin rpy="0 -0 0" xyz="0.014 -0.058 0.029"/>
      <inertia ixx="0.004" ixy="-0.001" ixz="0" iyy="0.006" iyz="0" izz="0.007"/>
    </inertial>
    <visual>
      <origin rpy="-1.04719755 0 0" xyz="0 0 0"/>
      <geometry>
        <mesh filename="package://atlas/meshes/r_clav.dae" scale="1 1 1"/>
      </geometry>
    </visual>
    <collision group="default">
      <origin rpy="0 1.5707963267949 0" xyz="0 -0.0697 0.0261"/>
      <geometry>
        <cylinder length="0.1525" radius="0.045"/>
      </geometry>
    </collision>
    <collision group="other">
      <origin rpy="-1.0472 0 0" xyz="-0.005 0.0074 -0.0538"/>
      <geometry>
        <box size="0.13 0.15 0.05"/>
      </geometry>
    </collision>
  </link>
  <link name="r_farm">
    <inertial>
      <mass value="0.981"/>
      <origin rpy="0 -0 0" xyz="0 -0.041 0"/>
      <inertia ixx="0.003" ixy="0" ixz="0" iyy="0.001" iyz="0" izz="0.003"/>
    </inertial>
    <visual>
      <origin rpy="0 -0 0" xyz="0 0.06 0"/>
      <geometry>
        <mesh filename="package://atlas/meshes/r_farm.dae" scale="1 1 1"/>
      </geometry>
    </visual>
    <collision group="default">
      <origin rpy="0 1.5708 0" xyz="0.0 -0.065 0.004"/>
      <geometry>
        <cylinder length="0.125" radius="0.045"/>
      </geometry>
    </collision>
    <collision group="other">
      <origin rpy="0 0 0" xyz="0.001 -0.015 -0.002"/>
      <geometry>
        <box size="0.135 0.1 0.045"/>
      </geometry>
    </collision>
  </link>
  <link name="r_foot">
    <inertial>
      <mass value="0.867"/>
      <origin rpy="0 -0 0" xyz="0.027 0 -0.067"/>
      <inertia ixx="0.002" ixy="0" ixz="0" iyy="0.00350421" iyz="0" izz="0.00400651"/>
    </inertial>
    <visual>
      <origin rpy="0 -0 0" xyz="0 0 0"/>
      <geometry>
        <mesh filename="package://atlas/meshes/r_foot.dae" scale="1 1 1"/>
      </geometry>
    </visual>
    <!-- bottom -->
    <collision group="default">
      <origin rpy="0 0 0" xyz="0.048 0 -0.056119"/>
      <geometry>
        <box size="0.26 0.124887 0.05"/>
      </geometry>
    </collision>
    <!-- ankle FIXME: adding this collision body destabilizes robot, shouldn't
        <collision group="other">
          <origin xyz="0.0 0 -0.0528735" rpy="0 0 0"/>
          <geometry>
            <cylinder radius="0.0373" length="0.037827"/>
          </geometry>
        </collision>
        -->
  </link>
  <link name="r_hand">
    <inertial>
      <mass value="2.263"/>
      <origin rpy="0 -0 0" xyz="0 -0.093 0"/>
      <inertia ixx="0.01" ixy="0" ixz="0" iyy="0.002" iyz="0" izz="0.01"/>
    </inertial>
    <visual>
      <origin rpy="0 -0 0" xyz="0 0 0"/>
      <geometry>
        <mesh filename="package://atlas/meshes/r_hand.dae" scale="1 1 1"/>
      </geometry>
    </visual>
    <collision group="default">
      <origin rpy="1.5707963267949 0 0" xyz="0.001 -0.1 0.01"/>
      <geometry>
        <cylinder length="0.05" radius="0.03"/>
      </geometry>
    </collision>
    <collision group="other">
      <origin rpy="0 0 0" xyz="0.001 -0.05 0.01"/>
      <geometry>
        <box size="0.13 0.09 0.07"/>
      </geometry>
    </collision>
  </link>
  <link name="r_larm">
    <inertial>
      <mass value="2.148"/>
      <origin rpy="0 -0 0" xyz="-0.003 -0.099 -0.014"/>
      <inertia ixx="0.005" ixy="0" ixz="0" iyy="0.003" iyz="0" izz="0.006"/>
    </inertial>
    <visual>
      <origin rpy="0 -0 0" xyz="0 0 0"/>
      <geometry>
        <mesh filename="package://atlas/meshes/r_larm.dae" scale="1.0 1.0 1.0"/>
      </geometry>
    </visual>
    <collision group="default">
      <origin rpy="1.5707963267949 0 0" xyz="0.001 -0.127 0.00"/>
      <geometry>
        <cylinder length="0.125" radius="0.045"/>
      </geometry>
    </collision>
    <collision group="other">
      <origin rpy="0 0 0" xyz="0.001 -0.051 0.0"/>
      <geometry>
        <box size="0.135 0.15 0.06"/>
      </geometry>
    </collision>
  </link>
  <link name="r_lglut">
    <inertial>
      <mass value="0.803"/>
      <origin rpy="0 -0 0" xyz="0.0133341 -0.0170484 -0.0312052"/>
      <inertia ixx="0.0453457" ixy="2.24344e-05" ixz="2.50508e-06" iyy="0.0174182" iyz="-0.000137862" izz="0.0071591"/>
    </inertial>
    <visual>
      <origin rpy="0 -0 0" xyz="0 0 0"/>
      <geometry>
        <mesh filename="package://atlas/meshes/r_lglut.dae" scale="1.0 1.0 1.0"/>
      </geometry>
    </visual>
    <collision group="default">
      <origin rpy="1.5707963267949 0 0" xyz="0.049968 -0.022488 -0.0501165"/>
      <geometry>
        <cylinder length="0.060306" radius="0.02009687"/>
      </geometry>
    </collision>
    <collision group="other">
      <origin rpy="0 1.5707963267949 0" xyz="0 0 0"/>
      <geometry>
        <cylinder length="0.12" radius="0.02"/>
      </geometry>
    </collision>
  </link>
  <link name="r_lleg">
    <inertial>
      <mass value="4.367"/>
      <origin rpy="0 -0 0" xyz="0.001 0 -0.187"/>
      <inertia ixx="0.077" ixy="-0" ixz="-0.003" iyy="0.076" iyz="-0" izz="0.01"/>
    </inertial>
    <visual>
      <origin rpy="0 -0 0" xyz="0 0 0"/>
      <geometry>
        <mesh filename="package://atlas/meshes/r_lleg.dae" scale="1.0 1.0 1.0"/>
      </geometry>
    </visual>
    <collision group="default">
      <origin rpy="0 0.10 0" xyz="0.02 -0.00295 -0.18"/>
      <geometry>
        <cylinder length="0.40" radius="0.07"/>
      </geometry>
    </collision>
  </link>
  <link name="r_scap">
    <inertial>
      <mass value="2.707"/>
      <origin rpy="0 -0 0" xyz="-0.002 -0.108 0"/>
      <inertia ixx="0.01" ixy="0" ixz="0" iyy="0.005" iyz="0" izz="0.013"/>
    </inertial>
    <visual>
      <origin rpy="0 -0 0" xyz="0 0 0"/>
      <geometry>
        <mesh filename="package://atlas/meshes/r_scap.dae" scale="1 1 1"/>
      </geometry>
    </visual>
    <collision group="default">
      <origin rpy="1.5707963267949 0 0" xyz="0.001 -0.12651 0.01521"/>
      <geometry>
        <cylinder length="0.125" radius="0.045"/>
      </geometry>
    </collision>
    <collision group="other">
      <origin rpy="0 0 0" xyz="0.001 -0.05 0.016"/>
      <geometry>
        <box size="0.15 0.15 0.06"/>
      </geometry>
    </collision>
  </link>
  <link name="r_talus">
    <inertial>
      <mass value="0.867"/>
      <origin rpy="0 -0 0" xyz="0 0 0"/>
      <inertia ixx="0.001" ixy="0" ixz="0" iyy="0.00350421" iyz="0" izz="0.00400651"/>
    </inertial>
    <visual>
      <origin rpy="0 -0 0" xyz="0 0 0"/>
      <geometry>
        <mesh filename="package://atlas/meshes/r_talus.dae" scale="1 1 1"/>
      </geometry>
    </visual>
    <collision group="default">
      <origin rpy="0 1.5707963267949 0" xyz="0 0 0"/>
      <geometry>
        <cylinder length="0.029542" radius="0.010181"/>
      </geometry>
    </collision>
    <collision group="other">
      <origin rpy="1.5707963267949 0 0" xyz="0 0 0"/>
      <geometry>
        <cylinder length="0.010059" radius="0.010348"/>
      </geometry>
    </collision>
  </link>
  <link name="r_uarm">
    <inertial>
      <mass value="1.881"/>
      <origin rpy="0 -0 0" xyz="0.007 -0.114 0.008"/>
      <inertia ixx="0.002" ixy="0" ixz="0" iyy="0.003" iyz="0" izz="0.003"/>
    </inertial>
    <visual>
      <origin rpy="0 -0 0" xyz="0 0 0"/>
      <geometry>
        <mesh filename="package://atlas/meshes/r_uarm.dae" scale="1.0 1.0 1.0"/>
      </geometry>
    </visual>
    <collision group="default">
      <origin rpy="0 1.5708 0" xyz="0.001 -0.111 0.0"/>
      <geometry>
        <cylinder length="0.125" radius="0.045"/>
      </geometry>
    </collision>
    <collision group="other">
      <origin rpy="0 1.5707963267949 0" xyz="0.001 -0.043 0.01"/>
      <geometry>
        <box size="0.04 0.07 0.13"/>
      </geometry>
    </collision>
  </link>
  <link name="r_uglut">
    <inertial>
      <mass value="1.51622"/>
      <origin rpy="0 -0 0" xyz="0.00529262 0.00344732 0.00313046"/>
      <inertia ixx="0.0327037" ixy="3.79607e-08" ixz="-2.79549e-05" iyy="0.0174182" iyz="3.2735e-08" izz="0.0071591"/>
    </inertial>
    <visual>
      <origin rpy="0 -0 0" xyz="0 0 0"/>
      <geometry>
        <mesh filename="package://atlas/meshes/r_uglut.dae" scale="1.0 1.0 1.0"/>
      </geometry>
    </visual>
    <collision group="default">
      <origin rpy="0 1.5707963267949 0" xyz="0 0 0"/>
      <geometry>
        <cylinder length="0.078396" radius="0.019096"/>
      </geometry>
    </collision>
    <collision group="other">
      <origin rpy="0 0 0" xyz="0 0 0"/>
      <geometry>
        <cylinder length="0.080842" radius="0.019841"/>
      </geometry>
    </collision>
  </link>
  <link name="r_uleg">
    <inertial>
      <mass value="7.227"/>
      <origin rpy="0 -0 0" xyz="0 0 -0.21"/>
      <inertia ixx="0.0453457" ixy="0" ixz="0" iyy="0.09" iyz="0" izz="0.0071591"/>
    </inertial>
    <visual>
      <origin rpy="0 -0 0" xyz="0 0 0"/>
      <geometry>
        <mesh filename="package://atlas/meshes/r_uleg.dae" scale="1.0 1.0 1.0"/>
      </geometry>
    </visual>
    <collision group="default">
      <origin rpy="0 0 0" xyz="-0.0179 -0.02085 -0.13"/>
      <geometry>
        <cylinder length="0.10" radius="0.1"/>
      </geometry>
    </collision>
    <collision group="other">
      <origin rpy="0 -0.3 0" xyz="-0.03 -0.01 -0.23"/>
      <geometry>
        <cylinder length="0.15" radius="0.07"/>
      </geometry>
    </collision>
    <collision group="other">
      <origin rpy="0 0.3 0" xyz="-0.005 -0.01 -0.23"/>
      <geometry>
        <cylinder length="0.15" radius="0.07"/>
      </geometry>
    </collision>
    <collision group="other">
      <origin rpy="0.25 0 0" xyz="-0.02 -0.03 -0.23"/>
      <geometry>
        <cylinder length="0.15" radius="0.07"/>
      </geometry>
    </collision>
  </link>
  <link name="utorso">
    <inertial>
      <mass value="15.2272"/>
      <origin rpy="0 -0 0" xyz="0.02 -0.001 0.211"/>
      <inertia ixx="0.395" ixy="0" ixz="0.083" iyy="0.544742" iyz="-0.003" izz="0.10973"/>
    </inertial>
    <visual>
      <origin rpy="0 -0 0" xyz="0 0 0"/>
      <geometry>
        <mesh filename="package://atlas/meshes/utorso.dae" scale="1 1 1"/>
      </geometry>
    </visual>
    <collision group="default">
      <origin rpy="0 -0 0" xyz="0.0446 0 0.1869"/>
      <geometry>
        <box size="0.3188 0.24 0.3162"/>
      </geometry>
    </collision>
    <collision group="other">
      <origin rpy="-0.5236 0 0" xyz="0.024 0.16 0.18"/>
      <geometry>
        <cylinder length="0.22375" radius="0.0363"/>
      </geometry>
    </collision>
    <collision group="other">
      <origin rpy="0.5236 0 0" xyz="0.024 -0.16 0.18"/>
      <geometry>
        <cylinder length="0.22375" radius="0.0363"/>
      </geometry>
    </collision>
  </link>
  <joint name="back_lbz" type="revolute">
    <origin rpy="0 -0 0" xyz="-0.0125 0 0"/>
    <axis xyz="0 0 1"/>
    <parent link="pelvis"/>
    <child link="ltorso"/>
    <dynamics damping="10" friction="0"/>
    <limit effort="124.016" lower="-0.610865" upper="0.610865" velocity="12"/>
    <safety_controller k_position="100" k_velocity="100" soft_lower_limit="-10.6109" soft_upper_limit="10.6109"/>
  </joint>
  <joint name="back_mby" type="revolute">
    <origin rpy="0 -0 0" xyz="0 0 0.09"/>
    <axis xyz="0 1 0"/>
    <parent link="ltorso"/>
    <child link="mtorso"/>
    <dynamics damping="10" friction="0"/>
    <limit effort="206.843" lower="-1.2" upper="1.28" velocity="12"/>
    <safety_controller k_position="100" k_velocity="100" soft_lower_limit="-11.2" soft_upper_limit="11.28"/>
  </joint>
  <joint name="back_ubx" type="revolute">
    <origin rpy="0 -0 0" xyz="0 0 0.05"/>
    <axis xyz="1 0 0"/>
    <parent link="mtorso"/>
    <child link="utorso"/>
    <dynamics damping="10" friction="0"/>
    <limit effort="94.91" lower="-0.790809" upper="0.790809" velocity="12"/>
    <safety_controller k_position="100" k_velocity="100" soft_lower_limit="-10.7908" soft_upper_limit="10.7908"/>
  </joint>
  <joint name="l_arm_elx" type="revolute">
    <origin rpy="0 -0 0" xyz="0 0.121 0.013"/>
    <axis xyz="1 0 0"/>
    <parent link="l_uarm"/>
    <child link="l_larm"/>
    <dynamics damping="1.0" friction="0"/>
    <limit effort="114" lower="0" upper="2.35619" velocity="12"/>
    <safety_controller k_position="100" k_velocity="100" soft_lower_limit="-10" soft_upper_limit="12.3562"/>
  </joint>
  <joint name="l_arm_ely" type="revolute">
    <origin rpy="0 -0 0" xyz="0 0.185 0"/>
    <axis xyz="0 1 0"/>
    <parent link="l_scap"/>
    <child link="l_uarm"/>
    <dynamics damping="1.0" friction="0"/>
    <limit effort="114" lower="0" upper="3.14159" velocity="12"/>
    <safety_controller k_position="100" k_velocity="100" soft_lower_limit="-10" soft_upper_limit="13.1416"/>
  </joint>
  <joint name="l_arm_mwx" type="revolute">
    <origin rpy="0 -0 0" xyz="0 0.058 0"/>
    <axis xyz="1 0 0"/>
    <parent link="l_farm"/>
    <child link="l_hand"/>
    <dynamics damping="1.0" friction="0"/>
    <limit effort="60" lower="-0.436" upper="1.571" velocity="12"/>
    <safety_controller k_position="100" k_velocity="100" soft_lower_limit="-10.436" soft_upper_limit="11.571"/>
  </joint>
  <joint name="l_arm_shx" type="revolute">
    <origin rpy="0 -0 0" xyz="0 0.075 0.036"/>
    <axis xyz="1 0 0"/>
    <parent link="l_clav"/>
    <child link="l_scap"/>
    <dynamics damping="1.0" friction="0"/>
    <limit effort="170" lower="-1.39626" upper="1.74533" velocity="12"/>
    <safety_controller k_position="100" k_velocity="100" soft_lower_limit="-11.3963" soft_upper_limit="11.7453"/>
  </joint>
  <joint name="l_arm_usy" type="revolute">
    <origin rpy="0 -0 0" xyz="0.024 0.221 0.289"/>
    <axis xyz="0 0.5 0.866025"/>
    <parent link="utorso"/>
    <child link="l_clav"/>
    <dynamics damping="1.0" friction="0"/>
    <limit effort="212" lower="-1.9635" upper="1.9635" velocity="12"/>
    <safety_controller k_position="100" k_velocity="100" soft_lower_limit="-11.9635" soft_upper_limit="11.9635"/>
  </joint>
  <joint name="l_arm_uwy" type="revolute">
    <origin rpy="0 -0 0" xyz="0 0.188 -0.013"/>
    <axis xyz="0 1 0"/>
    <parent link="l_larm"/>
    <child link="l_farm"/>
    <dynamics damping="1.0" friction="0"/>
    <limit effort="114" lower="-1.571" upper="1.571" velocity="12"/>
    <safety_controller k_position="100" k_velocity="100" soft_lower_limit="-11.571" soft_upper_limit="11.571"/>
  </joint>
  <joint name="l_leg_kny" type="revolute">
    <origin rpy="0 -0 0" xyz="-0.05 0 -0.374"/>
    <axis xyz="0 1 0"/>
    <parent link="l_uleg"/>
    <child link="l_lleg"/>
    <dynamics damping="1.0" friction="0"/>
    <limit effort="400" lower="0" upper="2.45" velocity="12"/>
    <safety_controller k_position="100" k_velocity="100" soft_lower_limit="-10" soft_upper_limit="12.45"/>
  </joint>
  <joint name="l_leg_lax" type="revolute">
    <origin rpy="0 -0 0" xyz="0 0 0"/>
    <axis xyz="1 0 0"/>
    <parent link="l_talus"/>
    <child link="l_foot"/>
    <dynamics damping="1.0" friction="0"/>
    <limit effort="90" lower="-0.436" upper="0.436" velocity="12"/>
    <safety_controller k_position="100" k_velocity="100" soft_lower_limit="-10.436" soft_upper_limit="10.436"/>
  </joint>
  <joint name="l_leg_lhy" type="revolute">
    <origin rpy="0 -0 0" xyz="0.05 0 -0.05"/>
    <axis xyz="0 1 0"/>
    <parent link="l_lglut"/>
    <child link="l_uleg"/>
    <dynamics damping="1.0" friction="0"/>
    <limit effort="260" lower="-1.75" upper="0.524" velocity="12"/>
    <safety_controller k_position="100" k_velocity="100" soft_lower_limit="-11.75" soft_upper_limit="10.524"/>
  </joint>
  <joint name="l_leg_mhx" type="revolute">
    <origin rpy="0 -0 0" xyz="0 0 0"/>
    <axis xyz="1 0 0"/>
    <parent link="l_uglut"/>
    <child link="l_lglut"/>
    <dynamics damping="1.0" friction="0"/>
    <limit effort="180" lower="-0.47" upper="0.495" velocity="12"/>
    <safety_controller k_position="100" k_velocity="100" soft_lower_limit="-10.47" soft_upper_limit="10.495"/>
  </joint>
  <joint name="l_leg_uay" type="revolute">
    <origin rpy="0 -0 0" xyz="0 0 -0.422"/>
    <axis xyz="0 1 0"/>
    <parent link="l_lleg"/>
    <child link="l_talus"/>
    <dynamics damping="1.0" friction="0"/>
    <limit effort="220" lower="-0.9" upper="0.698" velocity="12"/>
    <safety_controller k_position="100" k_velocity="100" soft_lower_limit="-10.698" soft_upper_limit="10.698"/>
  </joint>
  <joint name="l_leg_uhz" type="revolute">
    <origin rpy="0 -0 0" xyz="0 0.089 0"/>
    <axis xyz="0 0 1"/>
    <parent link="pelvis"/>
    <child link="l_uglut"/>
    <dynamics damping="1.0" friction="0"/>
    <limit effort="110" lower="-0.32" upper="1.14" velocity="12"/>
    <safety_controller k_position="100" k_velocity="100" soft_lower_limit="-10.32" soft_upper_limit="11.14"/>
  </joint>
  <joint name="neck_ay" type="revolute">
    <!-- per slides on sensor head kinematics 2013-02-13 -->
    <origin rpy="0 -0 0" xyz="0.21672 0 0.53796"/>
    <axis xyz="0 1 0"/>
    <parent link="utorso"/>
    <child link="head"/>
    <dynamics damping="1.0" friction="0"/>
    <!-- per slides on sensor head kinematics 2012-12-14 -->
    <limit effort="5" lower="-0.610865238" upper="1.13446401" velocity="12"/>
    <safety_controller k_position="100" k_velocity="100" soft_lower_limit="-10.610865238" soft_upper_limit="11.13446401"/>
  </joint>
  <joint name="r_arm_elx" type="revolute">
    <origin rpy="0 -0 0" xyz="0 -0.121 0.013"/>
    <axis xyz="1 0 0"/>
    <parent link="r_uarm"/>
    <child link="r_larm"/>
    <dynamics damping="1.0" friction="0"/>
    <limit effort="114" lower="-2.35619" upper="0" velocity="12"/>
    <safety_controller k_position="100" k_velocity="100" soft_lower_limit="-12.3562" soft_upper_limit="10"/>
  </joint>
  <joint name="r_arm_ely" type="revolute">
    <origin rpy="0 -0 0" xyz="0 -0.185 0"/>
    <axis xyz="0 1 0"/>
    <parent link="r_scap"/>
    <child link="r_uarm"/>
    <dynamics damping="1.0" friction="0"/>
    <limit effort="114" lower="0" upper="3.14159" velocity="12"/>
    <safety_controller k_position="100" k_velocity="100" soft_lower_limit="-10" soft_upper_limit="13.1416"/>
  </joint>
  <joint name="r_arm_mwx" type="revolute">
    <origin rpy="0 -0 0" xyz="0 -0.058 0"/>
    <axis xyz="1 0 0"/>
    <parent link="r_farm"/>
    <child link="r_hand"/>
    <dynamics damping="1.0" friction="0"/>
    <limit effort="60" lower="-1.571" upper="0.436" velocity="12"/>
    <safety_controller k_position="100" k_velocity="100" soft_lower_limit="-11.571" soft_upper_limit="10.436"/>
  </joint>
  <joint name="r_arm_shx" type="revolute">
    <origin rpy="0 -0 0" xyz="0 -0.075 0.036"/>
    <axis xyz="1 0 0"/>
    <parent link="r_clav"/>
    <child link="r_scap"/>
    <dynamics damping="1.0" friction="0"/>
    <limit effort="170" lower="-1.74533" upper="1.39626" velocity="12"/>
    <safety_controller k_position="100" k_velocity="100" soft_lower_limit="-11.7453" soft_upper_limit="11.3963"/>
  </joint>
  <joint name="r_arm_usy" type="revolute">
    <origin rpy="0 -0 0" xyz="0.024 -0.221 0.289"/>
    <axis xyz="0 0.5 -0.866025"/>
    <parent link="utorso"/>
    <child link="r_clav"/>
    <dynamics damping="1.0" friction="0"/>
    <limit effort="212" lower="-1.9635" upper="1.9635" velocity="12"/>
    <safety_controller k_position="100" k_velocity="100" soft_lower_limit="-11.9635" soft_upper_limit="11.9635"/>
  </joint>
  <joint name="r_arm_uwy" type="revolute">
    <origin rpy="0 -0 0" xyz="0 -0.188 -0.013"/>
    <axis xyz="0 1 0"/>
    <parent link="r_larm"/>
    <child link="r_farm"/>
    <dynamics damping="1.0" friction="0"/>
    <limit effort="114" lower="-1.571" upper="1.571" velocity="12"/>
    <safety_controller k_position="100" k_velocity="100" soft_lower_limit="-11.571" soft_upper_limit="11.571"/>
  </joint>
  <joint name="r_leg_kny" type="revolute">
    <origin rpy="0 -0 0" xyz="-0.05 0 -0.374"/>
    <axis xyz="0 1 0"/>
    <parent link="r_uleg"/>
    <child link="r_lleg"/>
    <dynamics damping="1.0" friction="0"/>
    <limit effort="400" lower="0" upper="2.45" velocity="12"/>
    <safety_controller k_position="100" k_velocity="100" soft_lower_limit="-10" soft_upper_limit="12.45"/>
  </joint>
  <joint name="r_leg_lax" type="revolute">
    <origin rpy="0 -0 0" xyz="0 0 0"/>
    <axis xyz="1 0 0"/>
    <parent link="r_talus"/>
    <child link="r_foot"/>
    <dynamics damping="1.0" friction="0"/>
    <limit effort="90" lower="-0.436" upper="0.436" velocity="12"/>
    <safety_controller k_position="100" k_velocity="100" soft_lower_limit="-10.436" soft_upper_limit="10.436"/>
  </joint>
  <joint name="r_leg_lhy" type="revolute">
    <origin rpy="0 -0 0" xyz="0.05 0 -0.05"/>
    <axis xyz="0 1 0"/>
    <parent link="r_lglut"/>
    <child link="r_uleg"/>
    <dynamics damping="1.0" friction="0"/>
    <limit effort="260" lower="-1.745" upper="0.524" velocity="12"/>
    <safety_controller k_position="100" k_velocity="100" soft_lower_limit="-11.745" soft_upper_limit="10.524"/>
  </joint>
  <joint name="r_leg_mhx" type="revolute">
    <origin rpy="0 -0 0" xyz="0 0 0"/>
    <axis xyz="1 0 0"/>
    <parent link="r_uglut"/>
    <child link="r_lglut"/>
    <dynamics damping="1.0" friction="0"/>
    <limit effort="180" lower="-0.495" upper="0.47" velocity="12"/>
    <safety_controller k_position="100" k_velocity="100" soft_lower_limit="-10.495" soft_upper_limit="10.47"/>
  </joint>
  <joint name="r_leg_uay" type="revolute">
    <origin rpy="0 -0 0" xyz="0 0 -0.422"/>
    <axis xyz="0 1 0"/>
    <parent link="r_lleg"/>
    <child link="r_talus"/>
    <dynamics damping="1.0" friction="0"/>
    <limit effort="220" lower="-0.9" upper="0.698" velocity="12"/>
    <safety_controller k_position="100" k_velocity="100" soft_lower_limit="-10.698" soft_upper_limit="10.698"/>
  </joint>
  <joint name="r_leg_uhz" type="revolute">
    <origin rpy="0 -0 0" xyz="0 -0.089 0"/>
    <axis xyz="0 0 1"/>
    <parent link="pelvis"/>
    <child link="r_uglut"/>
    <dynamics damping="1.0" friction="0"/>
    <limit effort="110" lower="-1.14" upper="0.32" velocity="12"/>
    <safety_controller k_position="100" k_velocity="100" soft_lower_limit="-11.14" soft_upper_limit="10.32"/>
  </joint>
  <gazebo>
    <!-- robot model offset -->
    <pose>0 0 0.93 0 0 0</pose>
  </gazebo>
  <gazebo>
    <plugin filename="libAtlasLQRPlugin.so" name="atlas_plugin"/>
    <plugin filename="libgazebo_ros_joint_trajectory.so" name="joint_trajectory_plugin">
      <topicName>joint_trajectory</topicName>
      <updateRate>1000.0</updateRate>
    </plugin>
    <!--
    <plugin filename="libgazebo_ros_controller_manager.so" name="gazebo_ros_controller_manager">
      <alwaysOn>true</alwaysOn>
      <updateRate>1000.0</updateRate>
    </plugin>
    -->
  </gazebo>
  <link name="imu_link">
    <inertial>
      <mass value="0.1"/>
      <origin xyz="0 0 0"/>
      <inertia ixx="0.001" ixy="0" ixz="0" iyy="0.001" iyz="0" izz="0.001"/>
    </inertial>
    <visual>
      <origin rpy="0 0 0" xyz="0 0 0"/>
      <geometry>
        <box size="0.01 0.01 0.01"/>
      </geometry>
    </visual>
  </link>
  <joint name="imu_joint" type="fixed">
    <parent link="pelvis"/>
    <child link="imu_link"/>
    <origin rpy="0 0 0" xyz="0.05991527603 0 -0.01415"/>
  </joint>
  <gazebo reference="imu_link">
    <!-- this is expected to be reparented to pelvis with appropriate offset
         when imu_link is reduced by fixed joint reduction -->
    <!-- todo: this is working with gazebo 1.4, need to write a unit test -->
    <sensor name="imu_sensor" type="imu">
      <always_on>1</always_on>
      <update_rate>1000.0</update_rate>
      <imu>
        <noise>
          <type>gaussian</type>
          <!-- Noise parameters from Boston Dynamics
               (http://gazebosim.org/wiki/Sensor_noise):
                 rates (rad/s): mean=0, stddev=2e-4
                 accels (m/s/s): mean=0, stddev=1.7e-2
                 rate bias (rad/s): 5e-6 - 1e-5
                 accel bias (m/s/s): 1e-1
               Experimentally, simulation provide rates with noise of
               about 1e-3 rad/s and accels with noise of about 1e-1 m/s/s.
               So we don't expect to see the noise unless number of inner iterations
               are increased.

               We will add bias.  In this model, bias is sampled once for rates
               and once for accels at startup; the sign (negative or positive)
               of each bias is then switched with equal probability.  Thereafter,
               the biases are fixed additive offsets.  We choose
               bias means and stddevs to produce biases close to the provided
               data. -->
          <rate>
            <mean>0.0</mean>
            <stddev>2e-4</stddev>
            <bias_mean>0.0000075</bias_mean>
            <bias_stddev>0.0000008</bias_stddev>
          </rate>
          <accel>
            <mean>0.0</mean>
            <stddev>1.7e-2</stddev>
            <bias_mean>0.1</bias_mean>
            <bias_stddev>0.001</bias_stddev>
          </accel>
        </noise>
      </imu>
    </sensor>
  </gazebo>
  <gazebo reference="l_arm_mwx">
    <provideFeedback>1</provideFeedback>
  </gazebo>
  <gazebo reference="r_arm_mwx">
    <provideFeedback>1</provideFeedback>
  </gazebo>
  <gazebo reference="l_leg_lax">
    <provideFeedback>1</provideFeedback>
    <cfmDamping>1</cfmDamping>
  </gazebo>
  <gazebo reference="r_leg_lax">
    <provideFeedback>1</provideFeedback>
    <cfmDamping>1</cfmDamping>
  </gazebo>
  <gazebo reference="r_foot">
    <!-- kp and kd for rubber -->
    <kp>1000000.0</kp>
    <kd>100.0</kd>
    <mu1>1.5</mu1>
    <mu2>1.5</mu2>
    <fdir1>1 0 0</fdir1>
    <maxVel>1.0</maxVel>
    <minDepth>0.00</minDepth>
  </gazebo>
  <gazebo reference="l_foot">
    <kp>1000000.0</kp>
    <kd>100.0</kd>
    <mu1>1.5</mu1>
    <mu2>1.5</mu2>
    <fdir1>1 0 0</fdir1>
    <maxVel>1.0</maxVel>
    <minDepth>0.00</minDepth>
  </gazebo>
  <gazebo reference="l_clav">
    <mu1>0.9</mu1>
    <mu2>0.9</mu2>
  </gazebo>
  <gazebo reference="l_farm">
    <mu1>0.9</mu1>
    <mu2>0.9</mu2>
  </gazebo>
  <gazebo reference="l_hand">
    <mu1>0.9</mu1>
    <mu2>0.9</mu2>
  </gazebo>
  <gazebo reference="l_larm">
    <mu1>0.9</mu1>
    <mu2>0.9</mu2>
  </gazebo>
  <gazebo reference="l_lglut">
    <mu1>0.9</mu1>
    <mu2>0.9</mu2>
  </gazebo>
  <gazebo reference="l_lleg">
    <mu1>0.9</mu1>
    <mu2>0.9</mu2>
  </gazebo>
  <gazebo reference="l_scap">
    <mu1>0.9</mu1>
    <mu2>0.9</mu2>
  </gazebo>
  <gazebo reference="l_talus">
    <mu1>0.9</mu1>
    <mu2>0.9</mu2>
  </gazebo>
  <gazebo reference="l_uarm">
    <mu1>0.9</mu1>
    <mu2>0.9</mu2>
  </gazebo>
  <gazebo reference="l_uglut">
    <mu1>0.9</mu1>
    <mu2>0.9</mu2>
  </gazebo>
  <gazebo reference="l_uleg">
    <mu1>0.9</mu1>
    <mu2>0.9</mu2>
  </gazebo>
  <gazebo reference="ltorso">
    <mu1>0.9</mu1>
    <mu2>0.9</mu2>
  </gazebo>
  <gazebo reference="mtorso">
    <mu1>0.9</mu1>
    <mu2>0.9</mu2>
  </gazebo>
  <gazebo reference="pelvis">
    <mu1>0.9</mu1>
    <mu2>0.9</mu2>
  </gazebo>
  <gazebo reference="r_clav">
    <mu1>0.9</mu1>
    <mu2>0.9</mu2>
  </gazebo>
  <gazebo reference="r_farm">
    <mu1>0.9</mu1>
    <mu2>0.9</mu2>
  </gazebo>
  <gazebo reference="r_hand">
    <mu1>0.9</mu1>
    <mu2>0.9</mu2>
  </gazebo>
  <gazebo reference="r_larm">
    <mu1>0.9</mu1>
    <mu2>0.9</mu2>
  </gazebo>
  <gazebo reference="r_lglut">
    <mu1>0.9</mu1>
    <mu2>0.9</mu2>
  </gazebo>
  <gazebo reference="r_lleg">
    <mu1>0.9</mu1>
    <mu2>0.9</mu2>
  </gazebo>
  <gazebo reference="r_scap">
    <mu1>0.9</mu1>
    <mu2>0.9</mu2>
  </gazebo>
  <gazebo reference="r_talus">
    <mu1>0.9</mu1>
    <mu2>0.9</mu2>
  </gazebo>
  <gazebo reference="r_uarm">
    <mu1>0.9</mu1>
    <mu2>0.9</mu2>
  </gazebo>
  <gazebo reference="r_uglut">
    <mu1>0.9</mu1>
    <mu2>0.9</mu2>
  </gazebo>
  <gazebo reference="r_uleg">
    <mu1>0.9</mu1>
    <mu2>0.9</mu2>
  </gazebo>
  <gazebo reference="utorso">
    <mu1>0.9</mu1>
    <mu2>0.9</mu2>
  </gazebo>
  <gazebo>
    <plugin filename="libgazebo_ros_p3d.so" name="gazebo_ros_p3d">
      <bodyName>pelvis</bodyName>
      <topicName>/ground_truth_odom</topicName>
      <alwaysOn>true</alwaysOn>
      <updateRate>100.0</updateRate>
    </plugin>
  </gazebo>
  <gazebo reference="r_foot">
    <!-- contact sensor -->
    <sensor name="r_foot_contact_sensor" type="contact">
      <update_rate>1000.0</update_rate>
      <always_on>1</always_on>
      <contact>
        <collision>r_foot_collision</collision>
        <topic>/r_foot_contact</topic>
      </contact>
    </sensor>
  </gazebo>
  <gazebo reference="l_foot">
    <!-- contact sensor -->
    <sensor name="l_foot_contact_sensor" type="contact">
      <update_rate>1000.0</update_rate>
      <always_on>1</always_on>
      <contact>
        <collision>l_foot_collision</collision>
        <topic>/l_foot_contact</topic>
      </contact>
    </sensor>
  </gazebo>
  <gazebo>
    <plugin filename="libgazebo_ros_force.so" name="gazebo_ros_force">
      <bodyName>pelvis</bodyName>
      <topicName>/atlas/apply_pelvis_force</topicName>
    </plugin>
  </gazebo>
  <gazebo reference="back_lbz">
    <cfmDamping>1</cfmDamping>
  </gazebo>
  <gazebo reference="back_mby">
    <cfmDamping>1</cfmDamping>
  </gazebo>
  <gazebo reference="back_ubx">
    <cfmDamping>1</cfmDamping>
  </gazebo>
  <gazebo reference="l_arm_elx">
    <cfmDamping>1</cfmDamping>
  </gazebo>
  <gazebo reference="l_arm_ely">
    <cfmDamping>1</cfmDamping>
  </gazebo>
  <gazebo reference="l_arm_mwx">
    <cfmDamping>1</cfmDamping>
  </gazebo>
  <gazebo reference="l_arm_shx">
    <cfmDamping>1</cfmDamping>
  </gazebo>
  <gazebo reference="l_arm_usy">
    <cfmDamping>1</cfmDamping>
  </gazebo>
  <gazebo reference="l_arm_uwy">
    <cfmDamping>1</cfmDamping>
  </gazebo>
  <gazebo reference="l_leg_kny">
    <cfmDamping>1</cfmDamping>
  </gazebo>
  <gazebo reference="l_leg_lhy">
    <cfmDamping>1</cfmDamping>
  </gazebo>
  <gazebo reference="l_leg_mhx">
    <cfmDamping>1</cfmDamping>
  </gazebo>
  <gazebo reference="l_leg_uay">
    <cfmDamping>1</cfmDamping>
  </gazebo>
  <gazebo reference="l_leg_uhz">
    <cfmDamping>1</cfmDamping>
  </gazebo>
  <gazebo reference="neck_ay">
    <cfmDamping>1</cfmDamping>
  </gazebo>
  <gazebo reference="r_arm_elx">
    <cfmDamping>1</cfmDamping>
  </gazebo>
  <gazebo reference="r_arm_ely">
    <cfmDamping>1</cfmDamping>
  </gazebo>
  <gazebo reference="r_arm_mwx">
    <cfmDamping>1</cfmDamping>
  </gazebo>
  <gazebo reference="r_arm_shx">
    <cfmDamping>1</cfmDamping>
  </gazebo>
  <gazebo reference="r_arm_usy">
    <cfmDamping>1</cfmDamping>
  </gazebo>
  <gazebo reference="r_arm_uwy">
    <cfmDamping>1</cfmDamping>
  </gazebo>
  <gazebo reference="r_leg_kny">
    <cfmDamping>1</cfmDamping>
  </gazebo>
  <gazebo reference="r_leg_lhy">
    <cfmDamping>1</cfmDamping>
  </gazebo>
  <gazebo reference="r_leg_mhx">
    <cfmDamping>1</cfmDamping>
  </gazebo>
  <gazebo reference="r_leg_uay">
    <cfmDamping>1</cfmDamping>
  </gazebo>
  <gazebo reference="r_leg_uhz">
    <cfmDamping>1</cfmDamping>
  </gazebo>
  <transmission name="head_hokuyo_trans" type="pr2_mechanism_model/SimpleTransmission">
    <joint name="hokuyo_joint"/>
    <actuator name="hokuyo_motor"/>
    <mechanicalReduction>1</mechanicalReduction>
  </transmission>
  <transmission name="back_lbz_trans" type="pr2_mechanism_model/SimpleTransmission">
    <joint name="back_lbz"/>
    <actuator name="back_lbz_motor"/>
    <mechanicalReduction>1</mechanicalReduction>
  </transmission>
  <transmission name="back_mby_trans" type="pr2_mechanism_model/SimpleTransmission">
    <actuator name="back_mby_motor"/>
    <joint name="back_mby"/>
    <mechanicalReduction>1</mechanicalReduction>
  </transmission>
  <transmission name="back_ubx_trans" type="pr2_mechanism_model/SimpleTransmission">
    <actuator name="back_ubx_motor"/>
    <joint name="back_ubx"/>
    <mechanicalReduction>1</mechanicalReduction>
  </transmission>
  <transmission name="l_arm_elx_trans" type="pr2_mechanism_model/SimpleTransmission">
    <actuator name="l_arm_elx_motor"/>
    <joint name="l_arm_elx"/>
    <mechanicalReduction>1</mechanicalReduction>
  </transmission>
  <transmission name="l_arm_ely_trans" type="pr2_mechanism_model/SimpleTransmission">
    <actuator name="l_arm_ely_motor"/>
    <joint name="l_arm_ely"/>
    <mechanicalReduction>1</mechanicalReduction>
  </transmission>
  <transmission name="l_arm_mwx_trans" type="pr2_mechanism_model/SimpleTransmission">
    <actuator name="l_arm_mwx_motor"/>
    <joint name="l_arm_mwx"/>
    <mechanicalReduction>1</mechanicalReduction>
  </transmission>
  <transmission name="l_arm_shx_trans" type="pr2_mechanism_model/SimpleTransmission">
    <actuator name="l_arm_shx_motor"/>
    <joint name="l_arm_shx"/>
    <mechanicalReduction>1</mechanicalReduction>
  </transmission>
  <transmission name="l_arm_usy_trans" type="pr2_mechanism_model/SimpleTransmission">
    <actuator name="l_arm_usy_motor"/>
    <joint name="l_arm_usy"/>
    <mechanicalReduction>1</mechanicalReduction>
  </transmission>
  <transmission name="l_arm_uwy_trans" type="pr2_mechanism_model/SimpleTransmission">
    <actuator name="l_arm_uwy_motor"/>
    <joint name="l_arm_uwy"/>
    <mechanicalReduction>1</mechanicalReduction>
  </transmission>
  <transmission name="l_leg_kny_trans" type="pr2_mechanism_model/SimpleTransmission">
    <actuator name="l_leg_kny_motor"/>
    <joint name="l_leg_kny"/>
    <mechanicalReduction>1</mechanicalReduction>
  </transmission>
  <transmission name="l_leg_lax_trans" type="pr2_mechanism_model/SimpleTransmission">
    <actuator name="l_leg_lax_motor"/>
    <joint name="l_leg_lax"/>
    <mechanicalReduction>1</mechanicalReduction>
  </transmission>
  <transmission name="l_leg_lhy_trans" type="pr2_mechanism_model/SimpleTransmission">
    <actuator name="l_leg_lhy_motor"/>
    <joint name="l_leg_lhy"/>
    <mechanicalReduction>1</mechanicalReduction>
  </transmission>
  <transmission name="l_leg_mhx_trans" type="pr2_mechanism_model/SimpleTransmission">
    <actuator name="l_leg_mhx_motor"/>
    <joint name="l_leg_mhx"/>
    <mechanicalReduction>1</mechanicalReduction>
  </transmission>
  <transmission name="l_leg_uay_trans" type="pr2_mechanism_model/SimpleTransmission">
    <actuator name="l_leg_uay_motor"/>
    <joint name="l_leg_uay"/>
    <mechanicalReduction>1</mechanicalReduction>
  </transmission>
  <transmission name="l_leg_uhz_trans" type="pr2_mechanism_model/SimpleTransmission">
    <actuator name="l_leg_uhz_motor"/>
    <joint name="l_leg_uhz"/>
    <mechanicalReduction>1</mechanicalReduction>
  </transmission>
  <transmission name="neck_ay_trans" type="pr2_mechanism_model/SimpleTransmission">
    <actuator name="neck_ay_motor"/>
    <joint name="neck_ay"/>
    <mechanicalReduction>1</mechanicalReduction>
  </transmission>
  <transmission name="r_arm_elx_trans" type="pr2_mechanism_model/SimpleTransmission">
    <actuator name="r_arm_elx_motor"/>
    <joint name="r_arm_elx"/>
    <mechanicalReduction>1</mechanicalReduction>
  </transmission>
  <transmission name="r_arm_ely_trans" type="pr2_mechanism_model/SimpleTransmission">
    <actuator name="r_arm_ely_motor"/>
    <joint name="r_arm_ely"/>
    <mechanicalReduction>1</mechanicalReduction>
  </transmission>
  <transmission name="r_arm_mwx_trans" type="pr2_mechanism_model/SimpleTransmission">
    <actuator name="r_arm_mwx_motor"/>
    <joint name="r_arm_mwx"/>
    <mechanicalReduction>1</mechanicalReduction>
  </transmission>
  <transmission name="r_arm_shx_trans" type="pr2_mechanism_model/SimpleTransmission">
    <actuator name="r_arm_shx_motor"/>
    <joint name="r_arm_shx"/>
    <mechanicalReduction>1</mechanicalReduction>
  </transmission>
  <transmission name="r_arm_usy_trans" type="pr2_mechanism_model/SimpleTransmission">
    <actuator name="r_arm_usy_motor"/>
    <joint name="r_arm_usy"/>
    <mechanicalReduction>1</mechanicalReduction>
  </transmission>
  <transmission name="r_arm_uwy_trans" type="pr2_mechanism_model/SimpleTransmission">
    <actuator name="r_arm_uwy_motor"/>
    <joint name="r_arm_uwy"/>
    <mechanicalReduction>1</mechanicalReduction>
  </transmission>
  <transmission name="r_leg_kny_trans" type="pr2_mechanism_model/SimpleTransmission">
    <actuator name="r_leg_kny_motor"/>
    <joint name="r_leg_kny"/>
    <mechanicalReduction>1</mechanicalReduction>
  </transmission>
  <transmission name="r_leg_lax_trans" type="pr2_mechanism_model/SimpleTransmission">
    <actuator name="r_leg_lax_motor"/>
    <joint name="r_leg_lax"/>
    <mechanicalReduction>1</mechanicalReduction>
  </transmission>
  <transmission name="r_leg_lhy_trans" type="pr2_mechanism_model/SimpleTransmission">
    <actuator name="r_leg_lhy_motor"/>
    <joint name="r_leg_lhy"/>
    <mechanicalReduction>1</mechanicalReduction>
  </transmission>
  <transmission name="r_leg_mhx_trans" type="pr2_mechanism_model/SimpleTransmission">
    <actuator name="r_leg_mhx_motor"/>
    <joint name="r_leg_mhx"/>
    <mechanicalReduction>1</mechanicalReduction>
  </transmission>
  <transmission name="r_leg_uay_trans" type="pr2_mechanism_model/SimpleTransmission">
    <actuator name="r_leg_uay_motor"/>
    <joint name="r_leg_uay"/>
    <mechanicalReduction>1</mechanicalReduction>
  </transmission>
  <transmission name="r_leg_uhz_trans" type="pr2_mechanism_model/SimpleTransmission">
    <actuator name="r_leg_uhz_motor"/>
    <joint name="r_leg_uhz"/>
    <mechanicalReduction>1</mechanicalReduction>
  </transmission>
  <link name="head">
	</link>
</robot>
